Workbook

Sheet Summary
B1: Late-entry BTC Up/Down bot — backtest summary
B2: Data: 288 five-minute windows, 15 Jun 2026 (UTC). Baseline = ideal fills, $20 stake, entry band 0.98–0.99, last 30 s to 3 s.
B4: Inputs (blue = edit)
B5: Taker fee rate (fee = shares × rate × p × (1−p)) | C5: 0.07
B6: Extra flat fee per share ($) | C6: 0
B7: Confidence z-score | C7: 1.96
B8: Windows in dataset | C8: 288
B10: Results (formulas, live from Trades sheet)
B11: Entries | C11: =COUNT(Trades!$A$2:$A$1000) -> 155
B12: Windows with no entry | C12: =C8-C11 -> 133
B13: Wins | C13: =SUM(Trades!$J$2:$J$1000) -> 154
B14: Losses | C14: =C11-C13 -> 1
B15: Win rate | C15: =IF(C11=0,0,C13/C11) -> 0.99354839
B16: Win-rate CI low (Wilson) | C16: =IF(C11=0,0,(C15+C7^2/(2*C11)-C7*SQRT(C15*(1-C15)/C11+C7^2/(4*C11^2)))/(1+C7^2/C11)) -> 0.96436349
B17: Win-rate CI high (Wilson) | C17: =IF(C11=0,0,(C15+C7^2/(2*C11)+C7*SQRT(C15*(1-C15)/C11+C7^2/(4*C11^2)))/(1+C7^2/C11)) -> 0.99886025
B18: Volume-weighted avg fill price | C18: =SUM(Trades!$H$2:$H$1000)/SUM(Trades!$G$2:$G$1000) -> 0.98328214
B19: Breakeven win rate (≈ avg fill + fee/share) | C19: =C18+(SUM(Trades!$L$2:$L$1000))/SUM(Trades!$G$2:$G$1000) -> 0.98443128
B20: Capital deployed ($) | C20: =SUM(Trades!$H$2:$H$1000) -> 3052.2962
B21: Gross P&L ($) | C21: =SUM(Trades!$K$2:$K$1000) -> 31.48728
B22: Fees ($) | C22: =SUM(Trades!$L$2:$L$1000) -> 3.5671593
B23: Net P&L ($) | C23: =C21-C22 -> 27.92012
B24: Net P&L per trade ($) | C24: =IF(C11=0,0,C23/C11) -> 0.18012981
B25: Return on capital deployed | C25: =IF(C20=0,0,C23/C20) -> 0.0091472513
B26: Average win ($, net of fee) | C26: =IFERROR(SUMIFS(Trades!$M$2:$M$1000,Trades!$J$2:$J$1000,1)/C13,0) -> 0.31135143
B27: Average loss ($, net of fee) | C27: =IFERROR(SUMIFS(Trades!$M$2:$M$1000,Trades!$J$2:$J$1000,0)/C14,0) -> -20.028
B28: Wins erased by one loss | C28: =IFERROR(-C27/C26,0) -> 64.326025
B29: Breakeven losses at this trade count | C29: =IFERROR(C11*C26/(C26-C27),0) -> 2.3727144
B30: Breakeven loss rate | C30: =IFERROR(C29/C11,0) -> 0.015307835
B31: Max drawdown ($) | C31: =MIN(Trades!$P$2:$P$1000) -> -20.028
B32: Avg entry time (s before close) | C32: =AVERAGE(Trades!$N$2:$N$1000) -> 19.293548
B33: Up entries | C33: =COUNTIF(Trades!$D$2:$D$1000,"Up") -> 85
B34: Down entries | C34: =COUNTIF(Trades!$D$2:$D$1000,"Down") -> 70
B36: What-if: net P&L if the trade set had k losses
B37: Losses (k) | C37: Net P&L ($)
B38: 0 | C38: =(C$11-B38)*C$26+B38*C$27 -> 48.259472
B39: 1 | C39: =(C$11-B39)*C$26+B39*C$27 -> 27.92012
B40: 2 | C40: =(C$11-B40)*C$26+B40*C$27 -> 7.580769
B41: 3 | C41: =(C$11-B41)*C$26+B41*C$27 -> -12.758582
B42: 4 | C42: =(C$11-B42)*C$26+B42*C$27 -> -33.097934
B43: 5 | C43: =(C$11-B43)*C$26+B43*C$27 -> -53.437285
...

Sheet Trades
A1: Market # | B1: Market | C1: Close (UTC) | D1: Side | E1: Ask seen | F1: Avg fill | G1: Shares | H1: Cost ($) | I1: Winner | J1: Win? (1/0) | K1: Gross P&L ($) | L1: Fee ($) | M1: Net P&L ($) | N1: Entered (s before close) | O1: Cum net P&L ($) | P1: Drawdown ($) | R1: To update: paste new trades under the last row in the blue columns (A–G, I, N) and copy the black formula columns (H, J–M, O–P) down. Summary ranges cover rows 2–1000.
A2: 1 | B2: Bitcoin Up or Down - June 14, 8:05PM-8:10PM ET | C2: 46188.007 | D2: Up | E2: 0.98 | F2: 0.98 | G2: 20.408163 | H2: =G2*F2 -> 20 | I2: Up | J2: =IF(D2=I2,1,0) -> 1 | K2: =J2*G2-H2 -> 0.40816327 | L2: =G2*Summary!$C$5*F2*(1-F2)+G2*Summary!$C$6 -> 0.028 | M2: =K2-L2 -> 0.38016327 | N2: 30 | O2: =SUMIFS($M$2:$M$1000,$C$2:$C$1000,"<="&C2) -> 0.38016327 | P2: =O2-_xlfn.MAXIFS($O$2:$O$1000,$C$2:$C$1000,"<="&C2) -> 0
A3: 4 | B3: Bitcoin Up or Down - June 14, 8:20PM-8:25PM ET | C3: 46188.017 | D3: Down | E3: 0.99 | F3: 0.99 | G3: 20.20202 | H3: =G3*F3 -> 20 | I3: Down | J3: =IF(D3=I3,1,0) -> 1 | K3: =J3*G3-H3 -> 0.2020202 | L3: =G3*Summary!$C$5*F3*(1-F3)+G3*Summary!$C$6 -> 0.014 | M3: =K3-L3 -> 0.1880202 | N3: 7.5 | O3: =SUMIFS($M$2:$M$1000,$C$2:$C$1000,"<="&C3) -> 0.56818347 | P3: =O3-_xlfn.MAXIFS($O$2:$O$1000,$C$2:$C$1000,"<="&C3) -> 0
A4: 5 | B4: Bitcoin Up or Down - June 14, 8:25PM-8:30PM ET | C4: 46188.021 | D4: Up | E4: 0.99 | F4: 0.99 | G4: 20.20202 | H4: =G4*F4 -> 20 | I4: Up | J4: =IF(D4=I4,1,0) -> 1 | K4: =J4*G4-H4 -> 0.2020202 | L4: =G4*Summary!$C$5*F4*(1-F4)+G4*Summary!$C$6 -> 0.014 | M4: =K4-L4 -> 0.1880202 | N4: 30 | O4: =SUMIFS($M$2:$M$1000,$C$2:$C$1000,"<="&C4) -> 0.75620367 | P4: =O4-_xlfn.MAXIFS($O$2:$O$1000,$C$2:$C$1000,"<="&C4) -> 0
A5: 8 | B5: Bitcoin Up or Down - June 14, 8:40PM-8:45PM ET | C5: 46188.031 | D5: Up | E5: 0.98 | F5: 0.98 | G5: 20.408163 | H5: =G5*F5 -> 20 | I5: Up | J5: =IF(D5=I5,1,0) -> 1 | K5: =J5*G5-H5 -> 0.40816327 | L5: =G5*Summary!$C$5*F5*(1-F5)+G5*Summary!$C$6 -> 0.028 | M5: =K5-L5 -> 0.38016327 | N5: 3 | O5: =SUMIFS($M$2:$M$1000,$C$2:$C$1000,"<="&C5) -> 1.1363669 | P5: =O5-_xlfn.MAXIFS($O$2:$O$1000,$C$2:$C$1000,"<="&C5) -> 0
A6: 9 | B6: Bitcoin Up or Down - June 14, 8:45PM-8:50PM ET | C6: 46188.035 | D6: Up | E6: 0.98 | F6: 0.98 | G6: 20.408163 | H6: =G6*F6 -> 20 | I6: Up | J6: =IF(D6=I6,1,0) -> 1 | K6: =J6*G6-H6 -> 0.40816327 | L6: =G6*Summary!$C$5*F6*(1-F6)+G6*Summary!$C$6 -> 0.028 | M6: =K6-L6 -> 0.38016327 | N6: 8.5 | O6: =SUMIFS($M$2:$M$1000,$C$2:$C$1000,"<="&C6) -> 1.5165302 | P6: =O6-_xlfn.MAXIFS($O$2:$O$1000,$C$2:$C$1000,"<="&C6) -> 0
A7: 10 | B7: Bitcoin Up or Down - June 14, 8:50PM-8:55PM ET | C7: 46188.038 | D7: Up | E7: 0.98 | F7: 0.98 | G7: 20.408163 | H7: =G7*F7 -> 20 | I7: Up | J7: =IF(D7=I7,1,0) -> 1 | K7: =J7*G7-H7 -> 0.40816327 | L7: =G7*Summary!$C$5*F7*(1-F7)+G7*Summary!$C$6 -> 0.028 | M7: =K7-L7 -> 0.38016327 | N7: 17.5 | O7: =SUMIFS($M$2:$M$1000,$C$2:$C$1000,"<="&C7) -> 1.8966935 | P7: =O7-_xlfn.MAXIFS($O$2:$O$1000,$C$2:$C$1000,"<="&C7) -> 0
A8: 11 | B8: Bitcoin Up or Down - June 14, 8:55PM-9:00PM ET | C8: 46188.042 | D8: Up | E8: 0.98 | F8: 0.98 | G8: 20.408163 | H8: =G8*F8 -> 20 | I8: Up | J8: =IF(D8=I8,1,0) -> 1 | K8: =J8*G8-H8 -> 0.40816327 | L8: =G8*Summary!$C$5*F8*(1-F8)+G8*Summary!$C$6 -> 0.028 | M8: =K8-L8 -> 0.38016327 | N8: 30 | O8: =SUMIFS($M$2:$M$1000,$C$2:$C$1000,"<="&C8) -> 2.2768567 | P8: =O8-_xlfn.MAXIFS($O$2:$O$1000,$C$2:$C$1000,"<="&C8) -> 0
A9: 14 | B9: Bitcoin Up or Down - June 14, 9:10PM-9:15PM ET | C9: 46188.052 | D9: Up | E9: 0.98 | F9: 0.98 | G9: 20.408163 | H9: =G9*F9 -> 20 | I9: Up | J9: =IF(D9=I9,1,0) -> 1 | K9: =J9*G9-H9 -> 0.40816327 | L9: =G9*Summary!$C$5*F9*(1-F9)+G9*Summary!$C$6 -> 0.028 | M9: =K9-L9 -> 0.38016327 | N9: 19.5 | O9: =SUMIFS($M$2:$M$1000,$C$2:$C$1000,"<="&C9) -> 2.65702 | P9: =O9-_xlfn.MAXIFS($O$2:$O$1000,$C$2:$C$1000,"<="&C9) -> 0
A10: 15 | B10: Bitcoin Up or Down - June 14, 9:15PM-9:20PM ET | C10: 46188.056 | D10: Down | E10: 0.98 | F10: 0.98 | G10: 20.408163 | H10: =G10*F10 -> 20 | I10: Down | J10: =IF(D10=I10,1,0) -> 1 | K10: =J10*G10-H10 -> 0.40816327 | L10: =G10*Summary!$C$5*F10*(1-F10)+G10*Summary!$C$6 -> 0.028 | M10: =K10-L10 -> 0.38016327 | N10: 10 | O10: =SUMIFS($M$2:$M$1000,$C$2:$C$1000,"<="&C10) -> 3.0371833 | P10: =O10-_xlfn.MAXIFS($O$2:$O$1000,$C$2:$C$1000,"<="&C10) -> 0
A11: 16 | B11: Bitcoin Up or Down - June 14, 9:20PM-9:25PM ET | C11: 46188.059 | D11: Down | E11: 0.98 | F11: 0.98 | G11: 20.408163 | H11: =G11*F11 -> 20 | I11: Down | J11: =IF(D11=I11,1,0) -> 1 | K11: =J11*G11-H11 -> 0.40816327 | L11: =G11*Summary!$C$5*F11*(1-F11)+G11*Summary!$C$6 -> 0.028 | M11: =K11-L11 -> 0.38016327 | N11: 30 | O11: =SUMIFS($M$2:$M$1000,$C$2:$C$1000,"<="&C11) -> 3.4173465 | P11: =O11-_xlfn.MAXIFS($O$2:$O$1000,$C$2:$C$1000,"<="&C11) -> 0
A12: 17 | B12: Bitcoin Up or Down - June 14, 9:25PM-9:30PM ET | C12: 46188.062 | D12: Down | E12: 0.98 | F12: 0.98 | G12: 20.408163 | H12: =G12*F12 -> 20 | I12: Down | J12: =IF(D12=I12,1,0) -> 1 | K12: =J12*G12-H12 -> 0.40816327 | L12: =G12*Summary!$C$5*F12*(1-F12)+G12*Summary!$C$6 -> 0.028 | M12: =K12-L12 -> 0.38016327 | N12: 12.5 | O12: =SUMIFS($M$2:$M$1000,$C$2:$C$1000,"<="&C12) -> 3.7975098 | P12: =O12-_xlfn.MAXIFS($O$2:$O$1000,$C$2:$C$1000,"<="&C12) -> 0
A13: 20 | B13: Bitcoin Up or Down - June 14, 9:40PM-9:45PM ET | C13: 46188.073 | D13: Up | E13: 0.98 | F13: 0.98 | G13: 20.408163 | H13: =G13*F13 -> 20 | I13: Up | J13: =IF(D13=I13,1,0) -> 1 | K13: =J13*G13-H13 -> 0.40816327 | L13: =G13*Summary!$C$5*F13*(1-F13)+G13*Summary!$C$6 -> 0.028 | M13: =K13-L13 -> 0.38016327 | N13: 5.5 | O13: =SUMIFS($M$2:$M$1000,$C$2:$C$1000,"<="&C13) -> 4.1776731 | P13: =O13-_xlfn.MAXIFS($O$2:$O$1000,$C$2:$C$1000,"<="&C13) -> 0
... A156: 287 | B156: Bitcoin Up or Down - June 15, 7:55PM-8:00PM ET | C156: 46189 | D156: Down | E156: 0.98 | F156: 0.98 | G156: 20.408163 | H156: =G156*F156 -> 20 | I156: Down | J156: =IF(D156=I156,1,0) -> 1 | K156: =J156*G156-H156 -> 0.40816327 | L156: =G156*Summary!$C$5*F156*(1-F156)+G156*Summary!$C$6 -> 0.028 | M156: =K156-L156 -> 0.38016327 | N156: 10 | O156: =SUMIFS($M$2:$M$1000,$C$2:$C$1000,"<="&C156) -> 27.92012 | P156: =O156-_xlfn.MAXIFS($O$2:$O$1000,$C$2:$C$1000,"<="&C156) -> -16.422633

Sheet Sensitivity
A1: Scenario results from the backtest (static values — rerun the backtest to refresh)
A3: Scenario | B3: Entries | C3: Wins | D3: Losses | E3: Win rate | F3: Avg fill | G3: Capital ($) | H3: Net P&L ($, 0 fee) | I3: P&L per trade ($) | J3: ROI
A4: baseline (ideal, 0 latency) | B4: 155 | C4: 154 | D4: 1 | E4: =IF(B4=0,0,C4/B4) -> 0.99354839 | F4: 0.9834 | G4: 3052 | H4: 31.49 | I4: =IF(B4=0,0,H4/B4) -> 0.20316129 | J4: =IF(G4=0,0,H4/G4) -> 0.010317824
A5: latency 250ms obs+fill | B5: 154 | C5: 153 | D5: 1 | E5: =IF(B5=0,0,C5/B5) -> 0.99350649 | F5: 0.9828 | G5: 3028 | H5: 32.93 | I5: =IF(B5=0,0,H5/B5) -> 0.21383117 | J5: =IF(G5=0,0,H5/G5) -> 0.010875165
A6: latency 500ms obs+fill | B6: 152 | C6: 151 | D6: 1 | E6: =IF(B6=0,0,C6/B6) -> 0.99342105 | F6: 0.9827 | G6: 2988 | H6: 32.82 | I6: =IF(B6=0,0,H6/B6) -> 0.21592105 | J6: =IF(G6=0,0,H6/G6) -> 0.010983936
A7: latency 1000ms obs+fill | B7: 144 | C7: 143 | D7: 1 | E7: =IF(B7=0,0,C7/B7) -> 0.99305556 | F7: 0.9823 | G7: 2844 | H7: 31.37 | I7: =IF(B7=0,0,H7/B7) -> 0.21784722 | J7: =IF(G7=0,0,H7/G7) -> 0.011030239
A8: latency 2000ms obs+fill | B8: 133 | C8: 132 | D8: 1 | E8: =IF(B8=0,0,C8/B8) -> 0.9924812 | F8: 0.9814 | G8: 2607 | H8: 30.6 | I8: =IF(B8=0,0,H8/B8) -> 0.23007519 | J8: =IF(G8=0,0,H8/G8) -> 0.011737629
A9: latency 1000ms fill only | B9: 149 | C9: 148 | D9: 1 | E9: =IF(B9=0,0,C9/B9) -> 0.99328859 | F9: 0.9828 | G9: 2944 | H9: 31.47 | I9: =IF(B9=0,0,H9/B9) -> 0.21120805 | J9: =IF(G9=0,0,H9/G9) -> 0.010689538
A10: entry window last 20s | B10: 128 | C10: 127 | D10: 1 | E10: =IF(B10=0,0,C10/B10) -> 0.9921875 | F10: 0.9833 | G10: 2528 | H10: 22.36 | I10: =IF(B10=0,0,H10/B10) -> 0.1746875 | J10: =IF(G10=0,0,H10/G10) -> 0.0088449367
A11: entry window last 10s | B11: 89 | C11: 88 | D11: 1 | E11: =IF(B11=0,0,C11/B11) -> 0.98876404 | F11: 0.9849 | G11: 1748 | H11: 6.41 | I11: =IF(B11=0,0,H11/B11) -> 0.072022472 | J11: =IF(G11=0,0,H11/G11) -> 0.0036670481
A12: band 0.97-0.99 | B12: 163 | C12: 160 | D12: 3 | E12: =IF(B12=0,0,C12/B12) -> 0.98159509 | F12: 0.9778 | G12: 3210 | H12: 11.63 | I12: =IF(B12=0,0,H12/B12) -> 0.071349693 | J12: =IF(G12=0,0,H12/G12) -> 0.003623053
A13: band 0.95-0.99 | B13: 173 | C13: 167 | D13: 6 | E13: =IF(B13=0,0,C13/B13) -> 0.96531792 | F13: 0.9663 | G13: 3365 | H13: -6.69 | I13: =IF(B13=0,0,H13/B13) -> -0.03867052 | J13: =IF(G13=0,0,H13/G13) -> -0.0019881129
A14: band 0.985-0.99 | B14: 146 | C14: 145 | D14: 1 | E14: =IF(B14=0,0,C14/B14) -> 0.99315068 | F14: 0.99 | G14: 2889 | H14: 8.98 | I14: =IF(B14=0,0,H14/B14) -> 0.061506849 | J14: =IF(G14=0,0,H14/G14) -> 0.003108342
A15: stake $100 | B15: 155 | C15: 154 | D15: 1 | E15: =IF(B15=0,0,C15/B15) -> 0.99354839 | F15: 0.9836 | G15: 14980 | H15: 151.19 | I15: =IF(B15=0,0,H15/B15) -> 0.97541935 | J15: =IF(G15=0,0,H15/G15) -> 0.01009279
... A18: poll 1.0s | B18: 153 | C18: 152 | D18: 1 | E18: =IF(B18=0,0,C18/B18) -> 0.99346405 | F18: 0.9838 | G18: 3008 | H18: 29.48 | I18: =IF(B18=0,0,H18/B18) -> 0.19267974 | J18: =IF(G18=0,0,H18/G18) -> 0.0098005319

Sheet Notes
A1: Method
A2: Book rebuilt per market from snapshots + deltas (BUY = bid, SELL = ask, size = new absolute level size, 0 = remove). Replay matched true snapshot entry decisions 94% of the time, same side every time both entered.
A3: Only the Up token book exists in the data (verified against outcomes). Down ask ladder = mirror of Up bids (price = 1 − bid price, same size).
A4: Bot logic replicated: poll every 0.5 s from 30 s to 3 s before close; best ask 0.98–0.99; limit 0.99; walk ask ladder spending ≤ $20; one entry per window; hold to settlement (win = $1/share).
A5: Latency scenarios: decision book taken half the latency earlier, fill book half the latency later.
A7: Assumptions I made
A8: Fee rate default 0.07 (Polymarket docs, crypto taker rate); dataset shows 0 bps — change Summary!C5 to 0 to match raw data.
A9: Poll timing phase assumed to start exactly 30 s before close.
A10: Fills use exchange state with no queue position or matching-engine delay.
A11: Sizes in the delta feed drift slightly from trade fills (a few shares at deep levels) — immaterial at $20.
A13: Caveats
A14: 288 windows from one day; 1 loss in 155 trades. Breakeven is about 2.5 losses per 155 trades, so the edge is not statistically established.
A15: Sensitivity sheet holds static outputs from the Python backtest; Summary and Trades are live formulas.
